Workbook

Sheet Daily Input
A1: 2026 | C1: Andrew Rockstroh | F1: Bryan Fletcher | I1: Coby De Lucia | L1: Dave Konkol | O1: Matt Delaune | R1: Ryan David | U1: Tyler Duprey | X1: Michael Wynkoop | AA1: Sydney Darrow | AD1: Michael Helton | AG1: Jacob Mann | AJ1: Brandon Steed | AM1: TEAM TOTALS
A2: Date | B2: Day | C2: Sets | D2: Shows | E2: CW | F2: Sets | G2: Shows | H2: CW | I2: Sets | J2: Shows | K2: CW | L2: Sets | M2: Shows | N2: CW | O2: Sets | P2: Shows | Q2: CW | R2: Sets | S2: Shows | T2: CW | U2: Sets | V2: Shows | W2: CW | X2: Sets | Y2: Shows | Z2: CW | AA2: Sets | AB2: Shows | AC2: CW | AD2: Sets | AE2: Shows | AF2: CW | AG2: Sets | AH2: Shows | AI2: CW | AJ2: Sets | AK2: Shows | AL2: CW | AM2: Sets | AN2: Shows | AO2: CW | AP2: Show% | AQ2: Close%
A3: JANUARY 2026
A4: 46023 | B4: Thu | C4: 1 | AM4: =C4+F4+I4+L4+O4+R4+U4+X4+AA4+AD4+AG4+AJ4 -> 1 | AN4: =D4+G4+J4+M4+P4+S4+V4+Y4+AB4+AE4+AH4+AK4 -> 0 | AO4: =E4+H4+K4+N4+Q4+T4+W4+Z4+AC4+AF4+AI4+AL4 -> 0 | AP4: =IF(AM4=0,0,AN4/AM4) -> 0 | AQ4: =IF(AN4=0,0,AO4/AN4) -> 0
A5: 46024 | B5: Fri | AM5: =C5+F5+I5+L5+O5+R5+U5+X5+AA5+AD5+AG5+AJ5 -> 0 | AN5: =D5+G5+J5+M5+P5+S5+V5+Y5+AB5+AE5+AH5+AK5 -> 0 | AO5: =E5+H5+K5+N5+Q5+T5+W5+Z5+AC5+AF5+AI5+AL5 -> 0 | AP5: =IF(AM5=0,0,AN5/AM5) -> 0 | AQ5: =IF(AN5=0,0,AO5/AN5) -> 0
A6: 46025 | B6: Sat | D6: 1 | AM6: =C6+F6+I6+L6+O6+R6+U6+X6+AA6+AD6+AG6+AJ6 -> 0 | AN6: =D6+G6+J6+M6+P6+S6+V6+Y6+AB6+AE6+AH6+AK6 -> 1 | AO6: =E6+H6+K6+N6+Q6+T6+W6+Z6+AC6+AF6+AI6+AL6 -> 0 | AP6: =IF(AM6=0,0,AN6/AM6) -> 0 | AQ6: =IF(AN6=0,0,AO6/AN6) -> 0
A7: 46026 | B7: Sun | AM7: =C7+F7+I7+L7+O7+R7+U7+X7+AA7+AD7+AG7+AJ7 -> 0 | AN7: =D7+G7+J7+M7+P7+S7+V7+Y7+AB7+AE7+AH7+AK7 -> 0 | AO7: =E7+H7+K7+N7+Q7+T7+W7+Z7+AC7+AF7+AI7+AL7 -> 0 | AP7: =IF(AM7=0,0,AN7/AM7) -> 0 | AQ7: =IF(AN7=0,0,AO7/AN7) -> 0
A8: 46027 | B8: Mon | C8: 4 | F8: 4 | L8: 1 | O8: 1 | R8: 1 | S8: 1 | AM8: =C8+F8+I8+L8+O8+R8+U8+X8+AA8+AD8+AG8+AJ8 -> 11 | AN8: =D8+G8+J8+M8+P8+S8+V8+Y8+AB8+AE8+AH8+AK8 -> 1 | AO8: =E8+H8+K8+N8+Q8+T8+W8+Z8+AC8+AF8+AI8+AL8 -> 0 | AP8: =IF(AM8=0,0,AN8/AM8) -> 0.090909091 | AQ8: =IF(AN8=0,0,AO8/AN8) -> 0
A9: 46028 | B9: Tue | C9: 3 | F9: 1 | I9: 1 | P9: 1 | R9: 2 | S9: 1 | AM9: =C9+F9+I9+L9+O9+R9+U9+X9+AA9+AD9+AG9+AJ9 -> 7 | AN9: =D9+G9+J9+M9+P9+S9+V9+Y9+AB9+AE9+AH9+AK9 -> 2 | AO9: =E9+H9+K9+N9+Q9+T9+W9+Z9+AC9+AF9+AI9+AL9 -> 0 | AP9: =IF(AM9=0,0,AN9/AM9) -> 0.28571429 | AQ9: =IF(AN9=0,0,AO9/AN9) -> 0
A10: 46029 | B10: Wed | C10: 2 | G10: 1 | L10: 2 | M10: 1 | O10: 1 | AM10: =C10+F10+I10+L10+O10+R10+U10+X10+AA10+AD10+AG10+AJ10 -> 5 | AN10: =D10+G10+J10+M10+P10+S10+V10+Y10+AB10+AE10+AH10+AK10 -> 2 | AO10: =E10+H10+K10+N10+Q10+T10+W10+Z10+AC10+AF10+AI10+AL10 -> 0 | AP10: =IF(AM10=0,0,AN10/AM10) -> 0.4 | AQ10: =IF(AN10=0,0,AO10/AN10) -> 0
A11: 46030 | B11: Thu | C11: 4 | D11: 1 | F11: 2 | O11: 1 | P11: 1 | R11: 1 | U11: 1 | AM11: =C11+F11+I11+L11+O11+R11+U11+X11+AA11+AD11+AG11+AJ11 -> 9 | AN11: =D11+G11+J11+M11+P11+S11+V11+Y11+AB11+AE11+AH11+AK11 -> 2 | AO11: =E11+H11+K11+N11+Q11+T11+W11+Z11+AC11+AF11+AI11+AL11 -> 0 | AP11: =IF(AM11=0,0,AN11/AM11) -> 0.22222222 | AQ11: =IF(AN11=0,0,AO11/AN11) -> 0
A12: 46031 | B12: Fri | D12: 4 | G12: 1 | R12: 1 | V12: 1 | AM12: =C12+F12+I12+L12+O12+R12+U12+X12+AA12+AD12+AG12+AJ12 -> 1 | AN12: =D12+G12+J12+M12+P12+S12+V12+Y12+AB12+AE12+AH12+AK12 -> 6 | AO12: =E12+H12+K12+N12+Q12+T12+W12+Z12+AC12+AF12+AI12+AL12 -> 0 | AP12: =IF(AM12=0,0,AN12/AM12) -> 6 | AQ12: =IF(AN12=0,0,AO12/AN12) -> 0
A13: 46032 | B13: Sat | AM13: =C13+F13+I13+L13+O13+R13+U13+X13+AA13+AD13+AG13+AJ13 -> 0 | AN13: =D13+G13+J13+M13+P13+S13+V13+Y13+AB13+AE13+AH13+AK13 -> 0 | AO13: =E13+H13+K13+N13+Q13+T13+W13+Z13+AC13+AF13+AI13+AL13 -> 0 | AP13: =IF(AM13=0,0,AN13/AM13) -> 0 | AQ13: =IF(AN13=0,0,AO13/AN13) -> 0
A14: 46033 | B14: Sun | AM14: =C14+F14+I14+L14+O14+R14+U14+X14+AA14+AD14+AG14+AJ14 -> 0 | AN14: =D14+G14+J14+M14+P14+S14+V14+Y14+AB14+AE14+AH14+AK14 -> 0 | AO14: =E14+H14+K14+N14+Q14+T14+W14+Z14+AC14+AF14+AI14+AL14 -> 0 | AP14: =IF(AM14=0,0,AN14/AM14) -> 0 | AQ14: =IF(AN14=0,0,AO14/AN14) -> 0
A15: 46034 | B15: Mon | C15: 3 | D15: 1 | F15: 2 | G15: 1 | L15: 2 | O15: 1 | R15: 1 | U15: 1 | AM15: =C15+F15+I15+L15+O15+R15+U15+X15+AA15+AD15+AG15+AJ15 -> 10 | AN15: =D15+G15+J15+M15+P15+S15+V15+Y15+AB15+AE15+AH15+AK15 -> 2 | AO15: =E15+H15+K15+N15+Q15+T15+W15+Z15+AC15+AF15+AI15+AL15 -> 0 | AP15: =IF(AM15=0,0,AN15/AM15) -> 0.2 | AQ15: =IF(AN15=0,0,AO15/AN15) -> 0
A16: 46035 | B16: Tue | D16: 1 | F16: 1 | L16: 2 | M16: 2 | R16: 3 | S16: 2 | V16: 1 | AM16: =C16+F16+I16+L16+O16+R16+U16+X16+AA16+AD16+AG16+AJ16 -> 6 | AN16: =D16+G16+J16+M16+P16+S16+V16+Y16+AB16+AE16+AH16+AK16 -> 6 | AO16: =E16+H16+K16+N16+Q16+T16+W16+Z16+AC16+AF16+AI16+AL16 -> 0 | AP16: =IF(AM16=0,0,AN16/AM16) -> 1 | AQ16: =IF(AN16=0,0,AO16/AN16) -> 0
A17: 46036 | B17: Wed | G17: 2 | L17: 2 | M17: 1 | U17: 2 | AM17: =C17+F17+I17+L17+O17+R17+U17+X17+AA17+AD17+AG17+AJ17 -> 4 | AN17: =D17+G17+J17+M17+P17+S17+V17+Y17+AB17+AE17+AH17+AK17 -> 3 | AO17: =E17+H17+K17+N17+Q17+T17+W17+Z17+AC17+AF17+AI17+AL17 -> 0 | AP17: =IF(AM17=0,0,AN17/AM17) -> 0.75 | AQ17: =IF(AN17=0,0,AO17/AN17) -> 0
A18: 46037 | B18: Thu | D18: 2 | F18: 1 | L18: 2 | O18: 1 | P18: 1 | R18: 1 | U18: 2 | AM18: =C18+F18+I18+L18+O18+R18+U18+X18+AA18+AD18+AG18+AJ18 -> 7 | AN18: =D18+G18+J18+M18+P18+S18+V18+Y18+AB18+AE18+AH18+AK18 -> 3 | AO18: =E18+H18+K18+N18+Q18+T18+W18+Z18+AC18+AF18+AI18+AL18 -> 0 | AP18: =IF(AM18=0,0,AN18/AM18) -> 0.42857143 | AQ18: =IF(AN18=0,0,AO18/AN18) -> 0
A19: 46038 | B19: Fri | C19: 3 | F19: 1 | M19: 1 | R19: 2 | S19: 1 | V19: 1 | AM19: =C19+F19+I19+L19+O19+R19+U19+X19+AA19+AD19+AG19+AJ19 -> 6 | AN19: =D19+G19+J19+M19+P19+S19+V19+Y19+AB19+AE19+AH19+AK19 -> 3 | AO19: =E19+H19+K19+N19+Q19+T19+W19+Z19+AC19+AF19+AI19+AL19 -> 0 | AP19: =IF(AM19=0,0,AN19/AM19) -> 0.5 | AQ19: =IF(AN19=0,0,AO19/AN19) -> 0
A20: 46039 | B20: Sat | AM20: =C20+F20+I20+L20+O20+R20+U20+X20+AA20+AD20+AG20+AJ20 -> 0 | AN20: =D20+G20+J20+M20+P20+S20+V20+Y20+AB20+AE20+AH20+AK20 -> 0 | AO20: =E20+H20+K20+N20+Q20+T20+W20+Z20+AC20+AF20+AI20+AL20 -> 0 | AP20: =IF(AM20=0,0,AN20/AM20) -> 0 | AQ20: =IF(AN20=0,0,AO20/AN20) -> 0
A21: 46040 | B21: Sun | AM21: =C21+F21+I21+L21+O21+R21+U21+X21+AA21+AD21+AG21+AJ21 -> 0 | AN21: =D21+G21+J21+M21+P21+S21+V21+Y21+AB21+AE21+AH21+AK21 -> 0 | AO21: =E21+H21+K21+N21+Q21+T21+W21+Z21+AC21+AF21+AI21+AL21 -> 0 | AP21: =IF(AM21=0,0,AN21/AM21) -> 0 | AQ21: =IF(AN21=0,0,AO21/AN21) -> 0
A22: 46041 | B22: Mon | AM22: =C22+F22+I22+L22+O22+R22+U22+X22+AA22+AD22+AG22+AJ22 -> 0 | AN22: =D22+G22+J22+M22+P22+S22+V22+Y22+AB22+AE22+AH22+AK22 -> 0 | AO22: =E22+H22+K22+N22+Q22+T22+W22+Z22+AC22+AF22+AI22+AL22 -> 0 | AP22: =IF(AM22=0,0,AN22/AM22) -> 0 | AQ22: =IF(AN22=0,0,AO22/AN22) -> 0
A23: 46042 | B23: Tue | O23: 3 | R23: 1 | S23: 1 | V23: 1 | AM23: =C23+F23+I23+L23+O23+R23+U23+X23+AA23+AD23+AG23+AJ23 -> 4 | AN23: =D23+G23+J23+M23+P23+S23+V23+Y23+AB23+AE23+AH23+AK23 -> 2 | AO23: =E23+H23+K23+N23+Q23+T23+W23+Z23+AC23+AF23+AI23+AL23 -> 0 | AP23: =IF(AM23=0,0,AN23/AM23) -> 0.5 | AQ23: =IF(AN23=0,0,AO23/AN23) -> 0
A24: 46043 | B24: Wed | C24: 1 | D24: 1 | G24: 1 | R24: 1 | S24: 1 | AA24: 1 | AM24: =C24+F24+I24+L24+O24+R24+U24+X24+AA24+AD24+AG24+AJ24 -> 3 | AN24: =D24+G24+J24+M24+P24+S24+V24+Y24+AB24+AE24+AH24+AK24 -> 3 | AO24: =E24+H24+K24+N24+Q24+T24+W24+Z24+AC24+AF24+AI24+AL24 -> 0 | AP24: =IF(AM24=0,0,AN24/AM24) -> 1 | AQ24: =IF(AN24=0,0,AO24/AN24) -> 0
A25: 46044 | B25: Thu | G25: 1 | L25: 2 | R25: 1 | V25: 1 | X25: 2 | AM25: =C25+F25+I25+L25+O25+R25+U25+X25+AA25+AD25+AG25+AJ25 -> 5 | AN25: =D25+G25+J25+M25+P25+S25+V25+Y25+AB25+AE25+AH25+AK25 -> 2 | AO25: =E25+H25+K25+N25+Q25+T25+W25+Z25+AC25+AF25+AI25+AL25 -> 0 | AP25: =IF(AM25=0,0,AN25/AM25) -> 0.4 | AQ25: =IF(AN25=0,0,AO25/AN25) -> 0
A26: 46045 | B26: Fri | C26: 1 | M26: 1 | O26: 1 | P26: 1 | R26: 1 | S26: 2 | U26: 1 | Y26: 1 | AA26: 1 | AM26: =C26+F26+I26+L26+O26+R26+U26+X26+AA26+AD26+AG26+AJ26 -> 5 | AN26: =D26+G26+J26+M26+P26+S26+V26+Y26+AB26+AE26+AH26+AK26 -> 5 | AO26: =E26+H26+K26+N26+Q26+T26+W26+Z26+AC26+AF26+AI26+AL26 -> 0 | AP26: =IF(AM26=0,0,AN26/AM26) -> 1 | AQ26: =IF(AN26=0,0,AO26/AN26) -> 0
A27: 46046 | B27: Sat | AM27: =C27+F27+I27+L27+O27+R27+U27+X27+AA27+AD27+AG27+AJ27 -> 0 | AN27: =D27+G27+J27+M27+P27+S27+V27+Y27+AB27+AE27+AH27+AK27 -> 0 | AO27: =E27+H27+K27+N27+Q27+T27+W27+Z27+AC27+AF27+AI27+AL27 -> 0 | AP27: =IF(AM27=0,0,AN27/AM27) -> 0 | AQ27: =IF(AN27=0,0,AO27/AN27) -> 0
A28: 46047 | B28: Sun | AM28: =C28+F28+I28+L28+O28+R28+U28+X28+AA28+AD28+AG28+AJ28 -> 0 | AN28: =D28+G28+J28+M28+P28+S28+V28+Y28+AB28+AE28+AH28+AK28 -> 0 | AO28: =E28+H28+K28+N28+Q28+T28+W28+Z28+AC28+AF28+AI28+AL28 -> 0 | AP28: =IF(AM28=0,0,AN28/AM28) -> 0 | AQ28: =IF(AN28=0,0,AO28/AN28) -> 0
A29: 46048 | B29: Mon | L29: 2 | M29: 1 | S29: 1 | AM29: =C29+F29+I29+L29+O29+R29+U29+X29+AA29+AD29+AG29+AJ29 -> 2 | AN29: =D29+G29+J29+M29+P29+S29+V29+Y29+AB29+AE29+AH29+AK29 -> 2 | AO29: =E29+H29+K29+N29+Q29+T29+W29+Z29+AC29+AF29+AI29+AL29 -> 0 | AP29: =IF(AM29=0,0,AN29/AM29) -> 1 | AQ29: =IF(AN29=0,0,AO29/AN29) -> 0
A30: 46049 | B30: Tue | R30: 1 | U30: 1 | X30: 1 | AM30: =C30+F30+I30+L30+O30+R30+U30+X30+AA30+AD30+AG30+AJ30 -> 3 | AN30: =D30+G30+J30+M30+P30+S30+V30+Y30+AB30+AE30+AH30+AK30 -> 0 | AO30: =E30+H30+K30+N30+Q30+T30+W30+Z30+AC30+AF30+AI30+AL30 -> 0 | AP30: =IF(AM30=0,0,AN30/AM30) -> 0 | AQ30: =IF(AN30=0,0,AO30/AN30) -> 0
A31: 46050 | B31: Wed | F31: 1 | L31: 1 | M31: 1 | P31: 1 | R31: 1 | S31: 1 | X31: 2 | AM31: =C31+F31+I31+L31+O31+R31+U31+X31+AA31+AD31+AG31+AJ31 -> 5 | AN31: =D31+G31+J31+M31+P31+S31+V31+Y31+AB31+AE31+AH31+AK31 -> 3 | AO31: =E31+H31+K31+N31+Q31+T31+W31+Z31+AC31+AF31+AI31+AL31 -> 0 | AP31: =IF(AM31=0,0,AN31/AM31) -> 0.6 | AQ31: =IF(AN31=0,0,AO31/AN31) -> 0
A32: 46051 | B32: Thu | D32: 1 | U32: 1 | V32: 1 | AB32: 1 | AM32: =C32+F32+I32+L32+O32+R32+U32+X32+AA32+AD32+AG32+AJ32 -> 1 | AN32: =D32+G32+J32+M32+P32+S32+V32+Y32+AB32+AE32+AH32+AK32 -> 3 | AO32: =E32+H32+K32+N32+Q32+T32+W32+Z32+AC32+AF32+AI32+AL32 -> 0 | AP32: =IF(AM32=0,0,AN32/AM32) -> 3 | AQ32: =IF(AN32=0,0,AO32/AN32) -> 0
A33: 46052 | B33: Fri | D33: 1 | F33: 1 | L33: 1 | M33: 2 | O33: 1 | R33: 1 | Y33: 1 | AB33: 1 | AM33: =C33+F33+I33+L33+O33+R33+U33+X33+AA33+AD33+AG33+AJ33 -> 4 | AN33: =D33+G33+J33+M33+P33+S33+V33+Y33+AB33+AE33+AH33+AK33 -> 5 | AO33: =E33+H33+K33+N33+Q33+T33+W33+Z33+AC33+AF33+AI33+AL33 -> 0 | AP33: =IF(AM33=0,0,AN33/AM33) -> 1.25 | AQ33: =IF(AN33=0,0,AO33/AN33) -> 0
A34: 46053 | B34: Sat | AM34: =C34+F34+I34+L34+O34+R34+U34+X34+AA34+AD34+AG34+AJ34 -> 0 | AN34: =D34+G34+J34+M34+P34+S34+V34+Y34+AB34+AE34+AH34+AK34 -> 0 | AO34: =E34+H34+K34+N34+Q34+T34+W34+Z34+AC34+AF34+AI34+AL34 -> 0 | AP34: =IF(AM34=0,0,AN34/AM34) -> 0 | AQ34: =IF(AN34=0,0,AO34/AN34) -> 0
A35: January Total | C35: =SUM(C4:C34) -> 22 | D35: =SUM(D4:D34) -> 13 | E35: =SUM(E4:E34) -> 0 | F35: =SUM(F4:F34) -> 14 | G35: =SUM(G4:G34) -> 7 | H35: =SUM(H4:H34) -> 0 | I35: =SUM(I4:I34) -> 1 | J35: =SUM(J4:J34) -> 0 | ... AO35: =SUM(AO4:AO34) -> 0 | AP35: =IF(AM35=0,0,AN35/AM35) -> 0.56565657 | AQ35: =IF(AN35=0,0,AO35/AN35) -> 0
A37: FEBRUARY 2026
A38: 46054 | B38: Sun | AM38: =C38+F38+I38+L38+O38+R38+U38+X38+AA38+AD38+AG38+AJ38 -> 0 | AN38: =D38+G38+J38+M38+P38+S38+V38+Y38+AB38+AE38+AH38+AK38 -> 0 | AO38: =E38+H38+K38+N38+Q38+T38+W38+Z38+AC38+AF38+AI38+AL38 -> 0 | AP38: =IF(AM38=0,0,AN38/AM38) -> 0 | AQ38: =IF(AN38=0,0,AO38/AN38) -> 0
A39: 46055 | B39: Mon | AM39: =C39+F39+I39+L39+O39+R39+U39+X39+AA39+AD39+AG39+AJ39 -> 0 | AN39: =D39+G39+J39+M39+P39+S39+V39+Y39+AB39+AE39+AH39+AK39 -> 0 | AO39: =E39+H39+K39+N39+Q39+T39+W39+Z39+AC39+AF39+AI39+AL39 -> 0 | AP39: =IF(AM39=0,0,AN39/AM39) -> 0 | AQ39: =IF(AN39=0,0,AO39/AN39) -> 0
A40: 46056 | B40: Tue | AM40: =C40+F40+I40+L40+O40+R40+U40+X40+AA40+AD40+AG40+AJ40 -> 0 | AN40: =D40+G40+J40+M40+P40+S40+V40+Y40+AB40+AE40+AH40+AK40 -> 0 | AO40: =E40+H40+K40+N40+Q40+T40+W40+Z40+AC40+AF40+AI40+AL40 -> 0 | AP40: =IF(AM40=0,0,AN40/AM40) -> 0 | AQ40: =IF(AN40=0,0,AO40/AN40) -> 0
A41: 46057 | B41: Wed | AM41: =C41+F41+I41+L41+O41+R41+U41+X41+AA41+AD41+AG41+AJ41 -> 0 | AN41: =D41+G41+J41+M41+P41+S41+V41+Y41+AB41+AE41+AH41+AK41 -> 0 | AO41: =E41+H41+K41+N41+Q41+T41+W41+Z41+AC41+AF41+AI41+AL41 -> 0 | AP41: =IF(AM41=0,0,AN41/AM41) -> 0 | AQ41: =IF(AN41=0,0,AO41/AN41) -> 0
...

Sheet Weekly Summary
A1: WEEKLY SUMMARY — 2026
A2: All 52 weeks with per-rep and team totals. Auto-populated from Daily Input.
A4: Week 1 (01/01 – 01/04)
A5: Rep | B5: Sets | C5: Shows | D5: Closed Won | E5: Show Rate | F5: Close Rate
A6: Andrew Rockstroh | B6: =SUM('Daily Input'!C4:C7) -> 1 | C6: =SUM('Daily Input'!D4:D7) -> 1 | D6: =SUM('Daily Input'!E4:E7) -> 0 | E6: =IF(B6=0,0,C6/B6) -> 1 | F6: =IF(C6=0,0,D6/C6) -> 0
A7: Bryan Fletcher | B7: =SUM('Daily Input'!F4:F7) -> 0 | C7: =SUM('Daily Input'!G4:G7) -> 0 | D7: =SUM('Daily Input'!H4:H7) -> 0 | E7: =IF(B7=0,0,C7/B7) -> 0 | F7: =IF(C7=0,0,D7/C7) -> 0
A8: Coby De Lucia | B8: =SUM('Daily Input'!I4:I7) -> 0 | C8: =SUM('Daily Input'!J4:J7) -> 0 | D8: =SUM('Daily Input'!K4:K7) -> 0 | E8: =IF(B8=0,0,C8/B8) -> 0 | F8: =IF(C8=0,0,D8/C8) -> 0
A9: Dave Konkol | B9: =SUM('Daily Input'!L4:L7) -> 0 | C9: =SUM('Daily Input'!M4:M7) -> 0 | D9: =SUM('Daily Input'!N4:N7) -> 0 | E9: =IF(B9=0,0,C9/B9) -> 0 | F9: =IF(C9=0,0,D9/C9) -> 0
A10: Matt Delaune | B10: =SUM('Daily Input'!O4:O7) -> 0 | C10: =SUM('Daily Input'!P4:P7) -> 0 | D10: =SUM('Daily Input'!Q4:Q7) -> 0 | E10: =IF(B10=0,0,C10/B10) -> 0 | F10: =IF(C10=0,0,D10/C10) -> 0
A11: Ryan David | B11: =SUM('Daily Input'!R4:R7) -> 0 | C11: =SUM('Daily Input'!S4:S7) -> 0 | D11: =SUM('Daily Input'!T4:T7) -> 0 | E11: =IF(B11=0,0,C11/B11) -> 0 | F11: =IF(C11=0,0,D11/C11) -> 0
A12: Tyler Duprey | B12: =SUM('Daily Input'!U4:U7) -> 0 | C12: =SUM('Daily Input'!V4:V7) -> 0 | D12: =SUM('Daily Input'!W4:W7) -> 0 | E12: =IF(B12=0,0,C12/B12) -> 0 | F12: =IF(C12=0,0,D12/C12) -> 0
A13: Michael Wynkoop | B13: =SUM('Daily Input'!X4:X7) -> 0 | C13: =SUM('Daily Input'!Y4:Y7) -> 0 | D13: =SUM('Daily Input'!Z4:Z7) -> 0 | E13: =IF(B13=0,0,C13/B13) -> 0 | F13: =IF(C13=0,0,D13/C13) -> 0
A14: Sydney Darrow | B14: =SUM('Daily Input'!AA4:AA7) -> 0 | C14: =SUM('Daily Input'!AB4:AB7) -> 0 | D14: =SUM('Daily Input'!AC4:AC7) -> 0 | E14: =IF(B14=0,0,C14/B14) -> 0 | F14: =IF(C14=0,0,D14/C14) -> 0
A15: Michael Helton | B15: =SUM('Daily Input'!AD4:AD7) -> 0 | C15: =SUM('Daily Input'!AE4:AE7) -> 0 | D15: =SUM('Daily Input'!AF4:AF7) -> 0 | E15: =IF(B15=0,0,C15/B15) -> 0 | F15: =IF(C15=0,0,D15/C15) -> 0
A16: Jacob Mann | B16: =SUM('Daily Input'!AG4:AG7) -> 0 | C16: =SUM('Daily Input'!AH4:AH7) -> 0 | D16: =SUM('Daily Input'!AI4:AI7) -> 0 | E16: =IF(B16=0,0,C16/B16) -> 0 | F16: =IF(C16=0,0,D16/C16) -> 0
A17: Brandon Steed | B17: =SUM('Daily Input'!AJ4:AJ7) -> 0 | C17: =SUM('Daily Input'!AK4:AK7) -> 0 | D17: =SUM('Daily Input'!AL4:AL7) -> 0 | E17: =IF(B17=0,0,C17/B17) -> 0 | F17: =IF(C17=0,0,D17/C17) -> 0
A18: TEAM TOTAL | B18: =SUM(B6:B17) -> 1 | C18: =SUM(C6:C17) -> 1 | D18: =SUM(D6:D17) -> 0 | E18: =IF(B18=0,0,C18/B18) -> 1 | F18: =IF(C18=0,0,D18/C18) -> 0
A20: Week 2 (01/05 – 01/11)
A21: Rep | B21: Sets | C21: Shows | D21: Closed Won | E21: Show Rate | F21: Close Rate
A22: Andrew Rockstroh | B22: =SUM('Daily Input'!C8:C14) -> 13 | C22: =SUM('Daily Input'!D8:D14) -> 5 | D22: =SUM('Daily Input'!E8:E14) -> 0 | E22: =IF(B22=0,0,C22/B22) -> 0.38461538 | F22: =IF(C22=0,0,D22/C22) -> 0
A23: Bryan Fletcher | B23: =SUM('Daily Input'!F8:F14) -> 7 | C23: =SUM('Daily Input'!G8:G14) -> 2 | D23: =SUM('Daily Input'!H8:H14) -> 0 | E23: =IF(B23=0,0,C23/B23) -> 0.28571429 | F23: =IF(C23=0,0,D23/C23) -> 0
A24: Coby De Lucia | B24: =SUM('Daily Input'!I8:I14) -> 1 | C24: =SUM('Daily Input'!J8:J14) -> 0 | D24: =SUM('Daily Input'!K8:K14) -> 0 | E24: =IF(B24=0,0,C24/B24) -> 0 | F24: =IF(C24=0,0,D24/C24) -> 0
A25: Dave Konkol | B25: =SUM('Daily Input'!L8:L14) -> 3 | C25: =SUM('Daily Input'!M8:M14) -> 1 | D25: =SUM('Daily Input'!N8:N14) -> 0 | E25: =IF(B25=0,0,C25/B25) -> 0.33333333 | F25: =IF(C25=0,0,D25/C25) -> 0
A26: Matt Delaune | B26: =SUM('Daily Input'!O8:O14) -> 3 | C26: =SUM('Daily Input'!P8:P14) -> 2 | D26: =SUM('Daily Input'!Q8:Q14) -> 0 | E26: =IF(B26=0,0,C26/B26) -> 0.66666667 | F26: =IF(C26=0,0,D26/C26) -> 0
A27: Ryan David | B27: =SUM('Daily Input'!R8:R14) -> 5 | C27: =SUM('Daily Input'!S8:S14) -> 2 | D27: =SUM('Daily Input'!T8:T14) -> 0 | E27: =IF(B27=0,0,C27/B27) -> 0.4 | F27: =IF(C27=0,0,D27/C27) -> 0
A28: Tyler Duprey | B28: =SUM('Daily Input'!U8:U14) -> 1 | C28: =SUM('Daily Input'!V8:V14) -> 1 | D28: =SUM('Daily Input'!W8:W14) -> 0 | E28: =IF(B28=0,0,C28/B28) -> 1 | F28: =IF(C28=0,0,D28/C28) -> 0
A29: Michael Wynkoop | B29: =SUM('Daily Input'!X8:X14) -> 0 | C29: =SUM('Daily Input'!Y8:Y14) -> 0 | D29: =SUM('Daily Input'!Z8:Z14) -> 0 | E29: =IF(B29=0,0,C29/B29) -> 0 | F29: =IF(C29=0,0,D29/C29) -> 0
A30: Sydney Darrow | B30: =SUM('Daily Input'!AA8:AA14) -> 0 | C30: =SUM('Daily Input'!AB8:AB14) -> 0 | D30: =SUM('Daily Input'!AC8:AC14) -> 0 | E30: =IF(B30=0,0,C30/B30) -> 0 | F30: =IF(C30=0,0,D30/C30) -> 0
A31: Michael Helton | B31: =SUM('Daily Input'!AD8:AD14) -> 0 | C31: =SUM('Daily Input'!AE8:AE14) -> 0 | D31: =SUM('Daily Input'!AF8:AF14) -> 0 | E31: =IF(B31=0,0,C31/B31) -> 0 | F31: =IF(C31=0,0,D31/C31) -> 0
A32: Jacob Mann | B32: =SUM('Daily Input'!AG8:AG14) -> 0 | C32: =SUM('Daily Input'!AH8:AH14) -> 0 | D32: =SUM('Daily Input'!AI8:AI14) -> 0 | E32: =IF(B32=0,0,C32/B32) -> 0 | F32: =IF(C32=0,0,D32/C32) -> 0
A33: Brandon Steed | B33: =SUM('Daily Input'!AJ8:AJ14) -> 0 | C33: =SUM('Daily Input'!AK8:AK14) -> 0 | D33: =SUM('Daily Input'!AL8:AL14) -> 0 | E33: =IF(B33=0,0,C33/B33) -> 0 | F33: =IF(C33=0,0,D33/C33) -> 0
A34: TEAM TOTAL | B34: =SUM(B22:B33) -> 33 | C34: =SUM(C22:C33) -> 13 | D34: =SUM(D22:D33) -> 0 | E34: =IF(B34=0,0,C34/B34) -> 0.39393939 | F34: =IF(C34=0,0,D34/C34) -> 0
A36: Week 3 (01/12 – 01/18)
A37: Rep | B37: Sets | C37: Shows | D37: Closed Won | E37: Show Rate | F37: Close Rate
A38: Andrew Rockstroh | B38: =SUM('Daily Input'!C15:C21) -> 6 | C38: =SUM('Daily Input'!D15:D21) -> 4 | D38: =SUM('Daily Input'!E15:E21) -> 0 | E38: =IF(B38=0,0,C38/B38) -> 0.66666667 | F38: =IF(C38=0,0,D38/C38) -> 0
A39: Bryan Fletcher | B39: =SUM('Daily Input'!F15:F21) -> 5 | C39: =SUM('Daily Input'!G15:G21) -> 3 | D39: =SUM('Daily Input'!H15:H21) -> 0 | E39: =IF(B39=0,0,C39/B39) -> 0.6 | F39: =IF(C39=0,0,D39/C39) -> 0
A40: Coby De Lucia | B40: =SUM('Daily Input'!I15:I21) -> 0 | C40: =SUM('Daily Input'!J15:J21) -> 0 | D40: =SUM('Daily Input'!K15:K21) -> 0 | E40: =IF(B40=0,0,C40/B40) -> 0 | F40: =IF(C40=0,0,D40/C40) -> 0
A41: Dave Konkol | B41: =SUM('Daily Input'!L15:L21) -> 8 | C41: =SUM('Daily Input'!M15:M21) -> 4 | D41: =SUM('Daily Input'!N15:N21) -> 0 | E41: =IF(B41=0,0,C41/B41) -> 0.5 | F41: =IF(C41=0,0,D41/C41) -> 0
A42: Matt Delaune | B42: =SUM('Daily Input'!O15:O21) -> 2 | C42: =SUM('Daily Input'!P15:P21) -> 1 | D42: =SUM('Daily Input'!Q15:Q21) -> 0 | E42: =IF(B42=0,0,C42/B42) -> 0.5 | F42: =IF(C42=0,0,D42/C42) -> 0
A43: Ryan David | B43: =SUM('Daily Input'!R15:R21) -> 7 | C43: =SUM('Daily Input'!S15:S21) -> 3 | D43: =SUM('Daily Input'!T15:T21) -> 0 | E43: =IF(B43=0,0,C43/B43) -> 0.42857143 | F43: =IF(C43=0,0,D43/C43) -> 0
...

Sheet Monthly Summary
A1: MONTHLY SUMMARY — 2026
A3: JANUARY 2026
A4: Rep | B4: Sets | C4: Shows | D4: Closed Won | E4: Show Rate | F4: Close Rate | G4: Avg Daily Sets | H4: Best Day Sets
A5: Andrew Rockstroh | B5: ='Daily Input'!C35 -> 22 | C5: ='Daily Input'!D35 -> 13 | D5: ='Daily Input'!E35 -> 0 | E5: =IF(B5=0,0,C5/B5) -> 0.59090909 | F5: =IF(C5=0,0,D5/C5) -> 0 | G5: =IFERROR(AVERAGEIF('Daily Input'!C4:C34,">0"),0) -> 2.4444444 | H5: =MAX('Daily Input'!C4:C34) -> 4
A6: Bryan Fletcher | B6: ='Daily Input'!F35 -> 14 | C6: ='Daily Input'!G35 -> 7 | D6: ='Daily Input'!H35 -> 0 | E6: =IF(B6=0,0,C6/B6) -> 0.5 | F6: =IF(C6=0,0,D6/C6) -> 0 | G6: =IFERROR(AVERAGEIF('Daily Input'!F4:F34,">0"),0) -> 1.5555556 | H6: =MAX('Daily Input'!F4:F34) -> 4
A7: Coby De Lucia | B7: ='Daily Input'!I35 -> 1 | C7: ='Daily Input'!J35 -> 0 | D7: ='Daily Input'!K35 -> 0 | E7: =IF(B7=0,0,C7/B7) -> 0 | F7: =IF(C7=0,0,D7/C7) -> 0 | G7: =IFERROR(AVERAGEIF('Daily Input'!I4:I34,">0"),0) -> 1 | H7: =MAX('Daily Input'!I4:I34) -> 1
A8: Dave Konkol | B8: ='Daily Input'!L35 -> 17 | C8: ='Daily Input'!M35 -> 10 | D8: ='Daily Input'!N35 -> 0 | E8: =IF(B8=0,0,C8/B8) -> 0.58823529 | F8: =IF(C8=0,0,D8/C8) -> 0 | G8: =IFERROR(AVERAGEIF('Daily Input'!L4:L34,">0"),0) -> 1.7 | H8: =MAX('Daily Input'!L4:L34) -> 2
A9: Matt Delaune | B9: ='Daily Input'!O35 -> 10 | C9: ='Daily Input'!P35 -> 5 | D9: ='Daily Input'!Q35 -> 0 | E9: =IF(B9=0,0,C9/B9) -> 0.5 | F9: =IF(C9=0,0,D9/C9) -> 0 | G9: =IFERROR(AVERAGEIF('Daily Input'!O4:O34,">0"),0) -> 1.25 | H9: =MAX('Daily Input'!O4:O34) -> 3
A10: Ryan David | B10: ='Daily Input'!R35 -> 19 | C10: ='Daily Input'!S35 -> 11 | D10: ='Daily Input'!T35 -> 0 | E10: =IF(B10=0,0,C10/B10) -> 0.57894737 | F10: =IF(C10=0,0,D10/C10) -> 0 | G10: =IFERROR(AVERAGEIF('Daily Input'!R4:R34,">0"),0) -> 1.2666667 | H10: =MAX('Daily Input'!R4:R34) -> 3
A11: Tyler Duprey | B11: ='Daily Input'!U35 -> 9 | C11: ='Daily Input'!V35 -> 6 | D11: ='Daily Input'!W35 -> 0 | E11: =IF(B11=0,0,C11/B11) -> 0.66666667 | F11: =IF(C11=0,0,D11/C11) -> 0 | G11: =IFERROR(AVERAGEIF('Daily Input'!U4:U34,">0"),0) -> 1.2857143 | H11: =MAX('Daily Input'!U4:U34) -> 2
A12: Michael Wynkoop | B12: ='Daily Input'!X35 -> 5 | C12: ='Daily Input'!Y35 -> 2 | D12: ='Daily Input'!Z35 -> 0 | E12: =IF(B12=0,0,C12/B12) -> 0.4 | F12: =IF(C12=0,0,D12/C12) -> 0 | G12: =IFERROR(AVERAGEIF('Daily Input'!X4:X34,">0"),0) -> 1.6666667 | H12: =MAX('Daily Input'!X4:X34) -> 2
A13: Sydney Darrow | B13: ='Daily Input'!AA35 -> 2 | C13: ='Daily Input'!AB35 -> 2 | D13: ='Daily Input'!AC35 -> 0 | E13: =IF(B13=0,0,C13/B13) -> 1 | F13: =IF(C13=0,0,D13/C13) -> 0 | G13: =IFERROR(AVERAGEIF('Daily Input'!AA4:AA34,">0"),0) -> 1 | H13: =MAX('Daily Input'!AA4:AA34) -> 1
A14: Michael Helton | B14: ='Daily Input'!AD35 -> 0 | C14: ='Daily Input'!AE35 -> 0 | D14: ='Daily Input'!AF35 -> 0 | E14: =IF(B14=0,0,C14/B14) -> 0 | F14: =IF(C14=0,0,D14/C14) -> 0 | G14: =IFERROR(AVERAGEIF('Daily Input'!AD4:AD34,">0"),0) -> 0 | H14: =MAX('Daily Input'!AD4:AD34) -> 0
A15: Jacob Mann | B15: ='Daily Input'!AG35 -> 0 | C15: ='Daily Input'!AH35 -> 0 | D15: ='Daily Input'!AI35 -> 0 | E15: =IF(B15=0,0,C15/B15) -> 0 | F15: =IF(C15=0,0,D15/C15) -> 0 | G15: =IFERROR(AVERAGEIF('Daily Input'!AG4:AG34,">0"),0) -> 0 | H15: =MAX('Daily Input'!AG4:AG34) -> 0
A16: Brandon Steed | B16: ='Daily Input'!AJ35 -> 0 | C16: ='Daily Input'!AK35 -> 0 | D16: ='Daily Input'!AL35 -> 0 | E16: =IF(B16=0,0,C16/B16) -> 0 | F16: =IF(C16=0,0,D16/C16) -> 0 | G16: =IFERROR(AVERAGEIF('Daily Input'!AJ4:AJ34,">0"),0) -> 0 | H16: =MAX('Daily Input'!AJ4:AJ34) -> 0
A17: TEAM TOTAL | B17: =SUM(B5:B16) -> 99 | C17: =SUM(C5:C16) -> 56 | D17: =SUM(D5:D16) -> 0 | E17: =IF(B17=0,0,C17/B17) -> 0.56565657 | F17: =IF(C17=0,0,D17/C17) -> 0 | G17: =IFERROR(AVERAGE(G5:G16),0) -> 1.0974206 | H17: =MAX(H5:H16) -> 4
A19: FEBRUARY 2026
A20: Rep | B20: Sets | C20: Shows | D20: Closed Won | E20: Show Rate | F20: Close Rate | G20: Avg Daily Sets | H20: Best Day Sets
A21: Andrew Rockstroh | B21: ='Daily Input'!C66 -> 0 | C21: ='Daily Input'!D66 -> 0 | D21: ='Daily Input'!E66 -> 0 | E21: =IF(B21=0,0,C21/B21) -> 0 | F21: =IF(C21=0,0,D21/C21) -> 0 | G21: =IFERROR(AVERAGEIF('Daily Input'!C38:C65,">0"),0) -> 0 | H21: =MAX('Daily Input'!C38:C65) -> 0
A22: Bryan Fletcher | B22: ='Daily Input'!F66 -> 0 | C22: ='Daily Input'!G66 -> 0 | D22: ='Daily Input'!H66 -> 0 | E22: =IF(B22=0,0,C22/B22) -> 0 | F22: =IF(C22=0,0,D22/C22) -> 0 | G22: =IFERROR(AVERAGEIF('Daily Input'!F38:F65,">0"),0) -> 0 | H22: =MAX('Daily Input'!F38:F65) -> 0
A23: Coby De Lucia | B23: ='Daily Input'!I66 -> 0 | C23: ='Daily Input'!J66 -> 0 | D23: ='Daily Input'!K66 -> 0 | E23: =IF(B23=0,0,C23/B23) -> 0 | F23: =IF(C23=0,0,D23/C23) -> 0 | G23: =IFERROR(AVERAGEIF('Daily Input'!I38:I65,">0"),0) -> 0 | H23: =MAX('Daily Input'!I38:I65) -> 0
A24: Dave Konkol | B24: ='Daily Input'!L66 -> 0 | C24: ='Daily Input'!M66 -> 0 | D24: ='Daily Input'!N66 -> 0 | E24: =IF(B24=0,0,C24/B24) -> 0 | F24: =IF(C24=0,0,D24/C24) -> 0 | G24: =IFERROR(AVERAGEIF('Daily Input'!L38:L65,">0"),0) -> 0 | H24: =MAX('Daily Input'!L38:L65) -> 0
A25: Matt Delaune | B25: ='Daily Input'!O66 -> 0 | C25: ='Daily Input'!P66 -> 0 | D25: ='Daily Input'!Q66 -> 0 | E25: =IF(B25=0,0,C25/B25) -> 0 | F25: =IF(C25=0,0,D25/C25) -> 0 | G25: =IFERROR(AVERAGEIF('Daily Input'!O38:O65,">0"),0) -> 0 | H25: =MAX('Daily Input'!O38:O65) -> 0
A26: Ryan David | B26: ='Daily Input'!R66 -> 0 | C26: ='Daily Input'!S66 -> 0 | D26: ='Daily Input'!T66 -> 0 | E26: =IF(B26=0,0,C26/B26) -> 0 | F26: =IF(C26=0,0,D26/C26) -> 0 | G26: =IFERROR(AVERAGEIF('Daily Input'!R38:R65,">0"),0) -> 0 | H26: =MAX('Daily Input'!R38:R65) -> 0
A27: Tyler Duprey | B27: ='Daily Input'!U66 -> 0 | C27: ='Daily Input'!V66 -> 0 | D27: ='Daily Input'!W66 -> 0 | E27: =IF(B27=0,0,C27/B27) -> 0 | F27: =IF(C27=0,0,D27/C27) -> 0 | G27: =IFERROR(AVERAGEIF('Daily Input'!U38:U65,">0"),0) -> 0 | H27: =MAX('Daily Input'!U38:U65) -> 0
A28: Michael Wynkoop | B28: ='Daily Input'!X66 -> 0 | C28: ='Daily Input'!Y66 -> 0 | D28: ='Daily Input'!Z66 -> 0 | E28: =IF(B28=0,0,C28/B28) -> 0 | F28: =IF(C28=0,0,D28/C28) -> 0 | G28: =IFERROR(AVERAGEIF('Daily Input'!X38:X65,">0"),0) -> 0 | H28: =MAX('Daily Input'!X38:X65) -> 0
A29: Sydney Darrow | B29: ='Daily Input'!AA66 -> 0 | C29: ='Daily Input'!AB66 -> 0 | D29: ='Daily Input'!AC66 -> 0 | E29: =IF(B29=0,0,C29/B29) -> 0 | F29: =IF(C29=0,0,D29/C29) -> 0 | G29: =IFERROR(AVERAGEIF('Daily Input'!AA38:AA65,">0"),0) -> 0 | H29: =MAX('Daily Input'!AA38:AA65) -> 0
A30: Michael Helton | B30: ='Daily Input'!AD66 -> 0 | C30: ='Daily Input'!AE66 -> 0 | D30: ='Daily Input'!AF66 -> 0 | E30: =IF(B30=0,0,C30/B30) -> 0 | F30: =IF(C30=0,0,D30/C30) -> 0 | G30: =IFERROR(AVERAGEIF('Daily Input'!AD38:AD65,">0"),0) -> 0 | H30: =MAX('Daily Input'!AD38:AD65) -> 0
A31: Jacob Mann | B31: ='Daily Input'!AG66 -> 0 | C31: ='Daily Input'!AH66 -> 0 | D31: ='Daily Input'!AI66 -> 0 | E31: =IF(B31=0,0,C31/B31) -> 0 | F31: =IF(C31=0,0,D31/C31) -> 0 | G31: =IFERROR(AVERAGEIF('Daily Input'!AG38:AG65,">0"),0) -> 0 | H31: =MAX('Daily Input'!AG38:AG65) -> 0
A32: Brandon Steed | B32: ='Daily Input'!AJ66 -> 0 | C32: ='Daily Input'!AK66 -> 0 | D32: ='Daily Input'!AL66 -> 0 | E32: =IF(B32=0,0,C32/B32) -> 0 | F32: =IF(C32=0,0,D32/C32) -> 0 | G32: =IFERROR(AVERAGEIF('Daily Input'!AJ38:AJ65,">0"),0) -> 0 | H32: =MAX('Daily Input'!AJ38:AJ65) -> 0
A33: TEAM TOTAL | B33: =SUM(B21:B32) -> 0 | C33: =SUM(C21:C32) -> 0 | D33: =SUM(D21:D32) -> 0 | E33: =IF(B33=0,0,C33/B33) -> 0 | F33: =IF(C33=0,0,D33/C33) -> 0 | G33: =IFERROR(AVERAGE(G21:G32),0) -> 0 | H33: =MAX(H21:H32) -> 0
A35: MARCH 2026
A36: Rep | B36: Sets | C36: Shows | D36: Closed Won | E36: Show Rate | F36: Close Rate | G36: Avg Daily Sets | H36: Best Day Sets
A37: Andrew Rockstroh | B37: ='Daily Input'!C100 -> 0 | C37: ='Daily Input'!D100 -> 0 | D37: ='Daily Input'!E100 -> 0 | E37: =IF(B37=0,0,C37/B37) -> 0 | F37: =IF(C37=0,0,D37/C37) -> 0 | G37: =IFERROR(AVERAGEIF('Daily Input'!C69:C99,">0"),0) -> 0 | H37: =MAX('Daily Input'!C69:C99) -> 0
A38: Bryan Fletcher | B38: ='Daily Input'!F100 -> 0 | C38: ='Daily Input'!G100 -> 0 | D38: ='Daily Input'!H100 -> 0 | E38: =IF(B38=0,0,C38/B38) -> 0 | F38: =IF(C38=0,0,D38/C38) -> 0 | G38: =IFERROR(AVERAGEIF('Daily Input'!F69:F99,">0"),0) -> 0 | H38: =MAX('Daily Input'!F69:F99) -> 0
A39: Coby De Lucia | B39: ='Daily Input'!I100 -> 0 | C39: ='Daily Input'!J100 -> 0 | D39: ='Daily Input'!K100 -> 0 | E39: =IF(B39=0,0,C39/B39) -> 0 | F39: =IF(C39=0,0,D39/C39) -> 0 | G39: =IFERROR(AVERAGEIF('Daily Input'!I69:I99,">0"),0) -> 0 | H39: =MAX('Daily Input'!I69:I99) -> 0
A40: Dave Konkol | B40: ='Daily Input'!L100 -> 0 | C40: ='Daily Input'!M100 -> 0 | D40: ='Daily Input'!N100 -> 0 | E40: =IF(B40=0,0,C40/B40) -> 0 | F40: =IF(C40=0,0,D40/C40) -> 0 | G40: =IFERROR(AVERAGEIF('Daily Input'!L69:L99,">0"),0) -> 0 | H40: =MAX('Daily Input'!L69:L99) -> 0
A41: Matt Delaune | B41: ='Daily Input'!O100 -> 0 | C41: ='Daily Input'!P100 -> 0 | D41: ='Daily Input'!Q100 -> 0 | E41: =IF(B41=0,0,C41/B41) -> 0 | F41: =IF(C41=0,0,D41/C41) -> 0 | G41: =IFERROR(AVERAGEIF('Daily Input'!O69:O99,">0"),0) -> 0 | H41: =MAX('Daily Input'!O69:O99) -> 0
A42: Ryan David | B42: ='Daily Input'!R100 -> 0 | C42: ='Daily Input'!S100 -> 0 | D42: ='Daily Input'!T100 -> 0 | E42: =IF(B42=0,0,C42/B42) -> 0 | F42: =IF(C42=0,0,D42/C42) -> 0 | G42: =IFERROR(AVERAGEIF('Daily Input'!R69:R99,">0"),0) -> 0 | H42: =MAX('Daily Input'!R69:R99) -> 0
A43: Tyler Duprey | B43: ='Daily Input'!U100 -> 0 | C43: ='Daily Input'!V100 -> 0 | D43: ='Daily Input'!W100 -> 0 | E43: =IF(B43=0,0,C43/B43) -> 0 | F43: =IF(C43=0,0,D43/C43) -> 0 | G43: =IFERROR(AVERAGEIF('Daily Input'!U69:U99,">0"),0) -> 0 | H43: =MAX('Daily Input'!U69:U99) -> 0
...

Sheet YTD Scoreboard
A1: YEAR-TO-DATE SCOREBOARD — 2026
A3: ANDREW ROCKSTROH
A4: Month | B4: Sets | C4: Shows | D4: Closed Won | E4: Show Rate | F4: Close Rate
A5: Jan | B5: ='Daily Input'!C35 -> 22 | C5: ='Daily Input'!D35 -> 13 | D5: ='Daily Input'!E35 -> 0 | E5: =IF(B5=0,0,C5/B5) -> 0.59090909 | F5: =IF(C5=0,0,D5/C5) -> 0
A6: Feb | B6: ='Daily Input'!C66 -> 0 | C6: ='Daily Input'!D66 -> 0 | D6: ='Daily Input'!E66 -> 0 | E6: =IF(B6=0,0,C6/B6) -> 0 | F6: =IF(C6=0,0,D6/C6) -> 0
A7: Mar | B7: ='Daily Input'!C100 -> 0 | C7: ='Daily Input'!D100 -> 0 | D7: ='Daily Input'!E100 -> 0 | E7: =IF(B7=0,0,C7/B7) -> 0 | F7: =IF(C7=0,0,D7/C7) -> 0
A8: Apr | B8: ='Daily Input'!C133 -> 0 | C8: ='Daily Input'!D133 -> 0 | D8: ='Daily Input'!E133 -> 0 | E8: =IF(B8=0,0,C8/B8) -> 0 | F8: =IF(C8=0,0,D8/C8) -> 0
A9: May | B9: ='Daily Input'!C167 -> 0 | C9: ='Daily Input'!D167 -> 0 | D9: ='Daily Input'!E167 -> 0 | E9: =IF(B9=0,0,C9/B9) -> 0 | F9: =IF(C9=0,0,D9/C9) -> 0
A10: Jun | B10: ='Daily Input'!C200 -> 0 | C10: ='Daily Input'!D200 -> 0 | D10: ='Daily Input'!E200 -> 0 | E10: =IF(B10=0,0,C10/B10) -> 0 | F10: =IF(C10=0,0,D10/C10) -> 0
A11: Jul | B11: ='Daily Input'!C234 -> 0 | C11: ='Daily Input'!D234 -> 0 | D11: ='Daily Input'!E234 -> 0 | E11: =IF(B11=0,0,C11/B11) -> 0 | F11: =IF(C11=0,0,D11/C11) -> 0
A12: Aug | B12: ='Daily Input'!C268 -> 0 | C12: ='Daily Input'!D268 -> 0 | D12: ='Daily Input'!E268 -> 0 | E12: =IF(B12=0,0,C12/B12) -> 0 | F12: =IF(C12=0,0,D12/C12) -> 0
A13: Sep | B13: ='Daily Input'!C301 -> 0 | C13: ='Daily Input'!D301 -> 0 | D13: ='Daily Input'!E301 -> 0 | E13: =IF(B13=0,0,C13/B13) -> 0 | F13: =IF(C13=0,0,D13/C13) -> 0
A14: Oct | B14: ='Daily Input'!C335 -> 0 | C14: ='Daily Input'!D335 -> 0 | D14: ='Daily Input'!E335 -> 0 | E14: =IF(B14=0,0,C14/B14) -> 0 | F14: =IF(C14=0,0,D14/C14) -> 0
A15: Nov | B15: ='Daily Input'!C368 -> 0 | C15: ='Daily Input'!D368 -> 0 | D15: ='Daily Input'!E368 -> 0 | E15: =IF(B15=0,0,C15/B15) -> 0 | F15: =IF(C15=0,0,D15/C15) -> 0
A16: Dec | B16: ='Daily Input'!C402 -> 0 | C16: ='Daily Input'!D402 -> 0 | D16: ='Daily Input'!E402 -> 0 | E16: =IF(B16=0,0,C16/B16) -> 0 | F16: =IF(C16=0,0,D16/C16) -> 0
A17: YTD TOTAL | B17: =SUM(B5:B16) -> 22 | C17: =SUM(C5:C16) -> 13 | D17: =SUM(D5:D16) -> 0 | E17: =IF(B17=0,0,C17/B17) -> 0.59090909 | F17: =IF(C17=0,0,D17/C17) -> 0
A19: BRYAN FLETCHER
A20: Month | B20: Sets | C20: Shows | D20: Closed Won | E20: Show Rate | F20: Close Rate
A21: Jan | B21: ='Daily Input'!F35 -> 14 | C21: ='Daily Input'!G35 -> 7 | D21: ='Daily Input'!H35 -> 0 | E21: =IF(B21=0,0,C21/B21) -> 0.5 | F21: =IF(C21=0,0,D21/C21) -> 0
A22: Feb | B22: ='Daily Input'!F66 -> 0 | C22: ='Daily Input'!G66 -> 0 | D22: ='Daily Input'!H66 -> 0 | E22: =IF(B22=0,0,C22/B22) -> 0 | F22: =IF(C22=0,0,D22/C22) -> 0
A23: Mar | B23: ='Daily Input'!F100 -> 0 | C23: ='Daily Input'!G100 -> 0 | D23: ='Daily Input'!H100 -> 0 | E23: =IF(B23=0,0,C23/B23) -> 0 | F23: =IF(C23=0,0,D23/C23) -> 0
A24: Apr | B24: ='Daily Input'!F133 -> 0 | C24: ='Daily Input'!G133 -> 0 | D24: ='Daily Input'!H133 -> 0 | E24: =IF(B24=0,0,C24/B24) -> 0 | F24: =IF(C24=0,0,D24/C24) -> 0
A25: May | B25: ='Daily Input'!F167 -> 0 | C25: ='Daily Input'!G167 -> 0 | D25: ='Daily Input'!H167 -> 0 | E25: =IF(B25=0,0,C25/B25) -> 0 | F25: =IF(C25=0,0,D25/C25) -> 0
A26: Jun | B26: ='Daily Input'!F200 -> 0 | C26: ='Daily Input'!G200 -> 0 | D26: ='Daily Input'!H200 -> 0 | E26: =IF(B26=0,0,C26/B26) -> 0 | F26: =IF(C26=0,0,D26/C26) -> 0
A27: Jul | B27: ='Daily Input'!F234 -> 0 | C27: ='Daily Input'!G234 -> 0 | D27: ='Daily Input'!H234 -> 0 | E27: =IF(B27=0,0,C27/B27) -> 0 | F27: =IF(C27=0,0,D27/C27) -> 0
A28: Aug | B28: ='Daily Input'!F268 -> 0 | C28: ='Daily Input'!G268 -> 0 | D28: ='Daily Input'!H268 -> 0 | E28: =IF(B28=0,0,C28/B28) -> 0 | F28: =IF(C28=0,0,D28/C28) -> 0
A29: Sep | B29: ='Daily Input'!F301 -> 0 | C29: ='Daily Input'!G301 -> 0 | D29: ='Daily Input'!H301 -> 0 | E29: =IF(B29=0,0,C29/B29) -> 0 | F29: =IF(C29=0,0,D29/C29) -> 0
A30: Oct | B30: ='Daily Input'!F335 -> 0 | C30: ='Daily Input'!G335 -> 0 | D30: ='Daily Input'!H335 -> 0 | E30: =IF(B30=0,0,C30/B30) -> 0 | F30: =IF(C30=0,0,D30/C30) -> 0
A31: Nov | B31: ='Daily Input'!F368 -> 0 | C31: ='Daily Input'!G368 -> 0 | D31: ='Daily Input'!H368 -> 0 | E31: =IF(B31=0,0,C31/B31) -> 0 | F31: =IF(C31=0,0,D31/C31) -> 0
A32: Dec | B32: ='Daily Input'!F402 -> 0 | C32: ='Daily Input'!G402 -> 0 | D32: ='Daily Input'!H402 -> 0 | E32: =IF(B32=0,0,C32/B32) -> 0 | F32: =IF(C32=0,0,D32/C32) -> 0
A33: YTD TOTAL | B33: =SUM(B21:B32) -> 14 | C33: =SUM(C21:C32) -> 7 | D33: =SUM(D21:D32) -> 0 | E33: =IF(B33=0,0,C33/B33) -> 0.5 | F33: =IF(C33=0,0,D33/C33) -> 0
A35: COBY DE LUCIA
A36: Month | B36: Sets | C36: Shows | D36: Closed Won | E36: Show Rate | F36: Close Rate
A37: Jan | B37: ='Daily Input'!I35 -> 1 | C37: ='Daily Input'!J35 -> 0 | D37: ='Daily Input'!K35 -> 0 | E37: =IF(B37=0,0,C37/B37) -> 0 | F37: =IF(C37=0,0,D37/C37) -> 0
A38: Feb | B38: ='Daily Input'!I66 -> 0 | C38: ='Daily Input'!J66 -> 0 | D38: ='Daily Input'!K66 -> 0 | E38: =IF(B38=0,0,C38/B38) -> 0 | F38: =IF(C38=0,0,D38/C38) -> 0
A39: Mar | B39: ='Daily Input'!I100 -> 0 | C39: ='Daily Input'!J100 -> 0 | D39: ='Daily Input'!K100 -> 0 | E39: =IF(B39=0,0,C39/B39) -> 0 | F39: =IF(C39=0,0,D39/C39) -> 0
A40: Apr | B40: ='Daily Input'!I133 -> 0 | C40: ='Daily Input'!J133 -> 0 | D40: ='Daily Input'!K133 -> 0 | E40: =IF(B40=0,0,C40/B40) -> 0 | F40: =IF(C40=0,0,D40/C40) -> 0
A41: May | B41: ='Daily Input'!I167 -> 0 | C41: ='Daily Input'!J167 -> 0 | D41: ='Daily Input'!K167 -> 0 | E41: =IF(B41=0,0,C41/B41) -> 0 | F41: =IF(C41=0,0,D41/C41) -> 0
A42: Jun | B42: ='Daily Input'!I200 -> 0 | C42: ='Daily Input'!J200 -> 0 | D42: ='Daily Input'!K200 -> 0 | E42: =IF(B42=0,0,C42/B42) -> 0 | F42: =IF(C42=0,0,D42/C42) -> 0
A43: Jul | B43: ='Daily Input'!I234 -> 0 | C43: ='Daily Input'!J234 -> 0 | D43: ='Daily Input'!K234 -> 0 | E43: =IF(B43=0,0,C43/B43) -> 0 | F43: =IF(C43=0,0,D43/C43) -> 0
...
